Workbook

Sheet Dashboard
B2: DASHBOARD PEMBAYARAN TAGIHAN WIFI
B6: TAGIHAN BELUM LUNAS | E6: TOTAL PELANGGAN | H6: TOTAL PENGELUARAN | K6: TOTAL PEMBAYARAN LUNAS RP
B8: RP : | C8: =SUM('Tagihan Pelanggan'!M4:M601) -> 15950000 | E8: =COUNTA(NamaPelanggan!C3:C602) -> 500 | H8: RP : | I8: =Pengeluaran!F3 -> 1915000 | K8: CASH : | L8: =SUM('Tagihan Pelanggan'!G4:G601) -> 75000
K9: BCA : | L9: =SUM('Tagihan Pelanggan'!H4:H601) -> 900000
K10: BRI : | L10: =SUM('Tagihan Pelanggan'!I4:I601) -> 42790000
K11: MANDIRI : | L11: =SUM('Tagihan Pelanggan'!J4:J601) -> 700000
K12: bni : | L12: =SUM('Tagihan Pelanggan'!K4:K601) -> 100000
K13: TOTAL KESELURUHAN RP
K15: RP : | L15: =L8+L9+L10+L11+L12 -> 44565000

Sheet NamaPelanggan
A1: @dropdown
B2: NO | C2: ID PELANGGAN | D2: NAMA PELANGGAN | E2: ALAMAT | F2: KODE PAKET | G2: PAKET | H2: HARGA
B3: 1 | C3: =IF(D3="","",LEFT(SUBSTITUTE(UPPER(E3)," ",""),3)&"-"&TEXT(B3,"000")) -> BLI-001 | D3: BAIHAKI | E3: BLIMBINGSARI | F3: 10 | G3: =IFERROR(VLOOKUP(F3,Setup!B:C,2,FALSE),"") -> 10mbps | H3: =IFERROR(VLOOKUP(G3,Setup!C:D,2,FALSE),"") -> 100000
B4: 2 | C4: =IF(D4="","",LEFT(SUBSTITUTE(UPPER(E4)," ",""),3)&"-"&TEXT(B4,"000")) -> BLI-002 | D4: BEDENG@BANANA | E4: BLIMBINGSARI | F4: 10 | G4: =IFERROR(VLOOKUP(F4,Setup!B:C,2,FALSE),"") -> 10mbps | H4: =IFERROR(VLOOKUP(G4,Setup!C:D,2,FALSE),"") -> 100000
B5: 3 | C5: =IF(D5="","",LEFT(SUBSTITUTE(UPPER(E5)," ",""),3)&"-"&TEXT(B5,"000")) -> BLI-003 | D5: DITA@NOK | E5: BLIMBINGSARI | F5: 10 | G5: =IFERROR(VLOOKUP(F5,Setup!B:C,2,FALSE),"") -> 10mbps | H5: =IFERROR(VLOOKUP(G5,Setup!C:D,2,FALSE),"") -> 100000
B6: 4 | C6: =IF(D6="","",LEFT(SUBSTITUTE(UPPER(E6)," ",""),3)&"-"&TEXT(B6,"000")) -> BLI-004 | D6: FIKRISEI | E6: BLIMBINGSARI | F6: 10 | G6: =IFERROR(VLOOKUP(F6,Setup!B:C,2,FALSE),"") -> 10mbps | H6: =IFERROR(VLOOKUP(G6,Setup!C:D,2,FALSE),"") -> 100000
B7: 5 | C7: =IF(D7="","",LEFT(SUBSTITUTE(UPPER(E7)," ",""),3)&"-"&TEXT(B7,"000")) -> BLI-005 | D7: MISTARA@YONO | E7: BLIMBINGSARI | F7: 10 | G7: =IFERROR(VLOOKUP(F7,Setup!B:C,2,FALSE),"") -> 10mbps | H7: =IFERROR(VLOOKUP(G7,Setup!C:D,2,FALSE),"") -> 100000
B8: 6 | C8: =IF(D8="","",LEFT(SUBSTITUTE(UPPER(E8)," ",""),3)&"-"&TEXT(B8,"000")) -> BLI-006 | D8: NAFIZ@MI | E8: BLIMBINGSARI | F8: 10 | G8: =IFERROR(VLOOKUP(F8,Setup!B:C,2,FALSE),"") -> 10mbps | H8: =IFERROR(VLOOKUP(G8,Setup!C:D,2,FALSE),"") -> 100000
B9: 7 | C9: =IF(D9="","",LEFT(SUBSTITUTE(UPPER(E9)," ",""),3)&"-"&TEXT(B9,"000")) -> BLI-007 | D9: PETRUK | E9: BLIMBINGSARI | F9: 10 | G9: =IFERROR(VLOOKUP(F9,Setup!B:C,2,FALSE),"") -> 10mbps | H9: =IFERROR(VLOOKUP(G9,Setup!C:D,2,FALSE),"") -> 100000
B10: 8 | C10: =IF(D10="","",LEFT(SUBSTITUTE(UPPER(E10)," ",""),3)&"-"&TEXT(B10,"000")) -> BLI-008 | D10: SABU | E10: BLIMBINGSARI | F10: 10 | G10: =IFERROR(VLOOKUP(F10,Setup!B:C,2,FALSE),"") -> 10mbps | H10: =IFERROR(VLOOKUP(G10,Setup!C:D,2,FALSE),"") -> 100000
B11: 9 | C11: =IF(D11="","",LEFT(SUBSTITUTE(UPPER(E11)," ",""),3)&"-"&TEXT(B11,"000")) -> BLI-009 | D11: SAROH@ANDIK | E11: BLIMBINGSARI | F11: 10 | G11: =IFERROR(VLOOKUP(F11,Setup!B:C,2,FALSE),"") -> 10mbps | H11: =IFERROR(VLOOKUP(G11,Setup!C:D,2,FALSE),"") -> 100000
B12: 10 | C12: =IF(D12="","",LEFT(SUBSTITUTE(UPPER(E12)," ",""),3)&"-"&TEXT(B12,"000")) -> BLI-010 | D12: SUNARYU | E12: BLIMBINGSARI | F12: 10 | G12: =IFERROR(VLOOKUP(F12,Setup!B:C,2,FALSE),"") -> 10mbps | H12: =IFERROR(VLOOKUP(G12,Setup!C:D,2,FALSE),"") -> 100000
B13: 11 | C13: =IF(D13="","",LEFT(SUBSTITUTE(UPPER(E13)," ",""),3)&"-"&TEXT(B13,"000")) -> BLI-011 | D13: lia muji | E13: BLIMBINGSARI | F13: 10 | G13: =IFERROR(VLOOKUP(F13,Setup!B:C,2,FALSE),"") -> 10mbps | H13: =IFERROR(VLOOKUP(G13,Setup!C:D,2,FALSE),"") -> 100000
B14: 12 | C14: =IF(D14="","",LEFT(SUBSTITUTE(UPPER(E14)," ",""),3)&"-"&TEXT(B14,"000")) -> BLI-012 | D14: YUSUF | E14: BLIMBINGSARI | F14: 10 | G14: =IFERROR(VLOOKUP(F14,Setup!B:C,2,FALSE),"") -> 10mbps | H14: =IFERROR(VLOOKUP(G14,Setup!C:D,2,FALSE),"") -> 100000
B15: 13 | C15: =IF(D15="","",LEFT(SUBSTITUTE(UPPER(E15)," ",""),3)&"-"&TEXT(B15,"000")) -> BLI-013 | D15: elisha | E15: BLIMBINGSARI | F15: 10 | G15: =IFERROR(VLOOKUP(F15,Setup!B:C,2,FALSE),"") -> 10mbps | H15: =IFERROR(VLOOKUP(G15,Setup!C:D,2,FALSE),"") -> 100000
B16: 14 | C16: =IF(D16="","",LEFT(SUBSTITUTE(UPPER(E16)," ",""),3)&"-"&TEXT(B16,"000")) -> BLI-014 | D16: SANTI | E16: BLIMBINGSARI | F16: 10 | G16: =IFERROR(VLOOKUP(F16,Setup!B:C,2,FALSE),"") -> 10mbps | H16: 50000
B17: 15 | C17: =IF(D17="","",LEFT(SUBSTITUTE(UPPER(E17)," ",""),3)&"-"&TEXT(B17,"000")) -> BLI-015 | D17: ROMI | E17: BLIMBINGSARI | F17: 10 | G17: =IFERROR(VLOOKUP(F17,Setup!B:C,2,FALSE),"") -> 10mbps | H17: 50000
B18: 16 | C18: =IF(D18="","",LEFT(SUBSTITUTE(UPPER(E18)," ",""),3)&"-"&TEXT(B18,"000")) -> BLI-016 | D18: MI@SUNANGIRI | E18: BLIMBINGSARI | F18: 10 | G18: =IFERROR(VLOOKUP(F18,Setup!B:C,2,FALSE),"") -> 10mbps | H18: 50000
B19: 17 | C19: =IF(D19="","",LEFT(SUBSTITUTE(UPPER(E19)," ",""),3)&"-"&TEXT(B19,"000")) -> BLI-017 | D19: MES@BANANA | E19: BLIMBINGSARI | F19: 10 | G19: =IFERROR(VLOOKUP(F19,Setup!B:C,2,FALSE),"") -> 10mbps | H19: =IFERROR(VLOOKUP(G19,Setup!C:D,2,FALSE),"") -> 100000
B20: 18 | C20: =IF(D20="","",LEFT(SUBSTITUTE(UPPER(E20)," ",""),3)&"-"&TEXT(B20,"000")) -> BLI-018 | D20: MES@BMT | E20: BLIMBINGSARI | F20: 10 | G20: =IFERROR(VLOOKUP(F20,Setup!B:C,2,FALSE),"") -> 10mbps | H20: =IFERROR(VLOOKUP(G20,Setup!C:D,2,FALSE),"") -> 100000
B21: 19 | C21: =IF(D21="","",LEFT(SUBSTITUTE(UPPER(E21)," ",""),3)&"-"&TEXT(B21,"000")) -> IDI-019 | D21: AKBARR | E21: IDINAN | F21: 10 | G21: =IFERROR(VLOOKUP(F21,Setup!B:C,2,FALSE),"") -> 10mbps | H21: =IFERROR(VLOOKUP(G21,Setup!C:D,2,FALSE),"") -> 100000
B22: 20 | C22: =IF(D22="","",LEFT(SUBSTITUTE(UPPER(E22)," ",""),3)&"-"&TEXT(B22,"000")) -> IDI-020 | D22: AKSORO | E22: IDINAN | F22: 10 | G22: =IFERROR(VLOOKUP(F22,Setup!B:C,2,FALSE),"") -> 10mbps | H22: =IFERROR(VLOOKUP(G22,Setup!C:D,2,FALSE),"") -> 100000
B23: 21 | C23: =IF(D23="","",LEFT(SUBSTITUTE(UPPER(E23)," ",""),3)&"-"&TEXT(B23,"000")) -> IDI-021 | D23: ALFI@SUN ( TERUSAN ) blimbing | E23: IDINAN | F23: 10 | G23: =IFERROR(VLOOKUP(F23,Setup!B:C,2,FALSE),"") -> 10mbps | H23: =IFERROR(VLOOKUP(G23,Setup!C:D,2,FALSE),"") -> 100000
B24: 22 | C24: =IF(D24="","",LEFT(SUBSTITUTE(UPPER(E24)," ",""),3)&"-"&TEXT(B24,"000")) -> IDI-022 | D24: ASIS | E24: IDINAN | F24: 10 | G24: =IFERROR(VLOOKUP(F24,Setup!B:C,2,FALSE),"") -> 10mbps | H24: =IFERROR(VLOOKUP(G24,Setup!C:D,2,FALSE),"") -> 100000
B25: 23 | C25: =IF(D25="","",LEFT(SUBSTITUTE(UPPER(E25)," ",""),3)&"-"&TEXT(B25,"000")) -> IDI-023 | D25: AYULESTARI | E25: IDINAN | F25: 10 | G25: =IFERROR(VLOOKUP(F25,Setup!B:C,2,FALSE),"") -> 10mbps | H25: =IFERROR(VLOOKUP(G25,Setup!C:D,2,FALSE),"") -> 100000
B26: 24 | C26: =IF(D26="","",LEFT(SUBSTITUTE(UPPER(E26)," ",""),3)&"-"&TEXT(B26,"000")) -> IDI-024 | D26: ELOK | E26: IDINAN | F26: 10 | G26: =IFERROR(VLOOKUP(F26,Setup!B:C,2,FALSE),"") -> 10mbps | H26: =IFERROR(VLOOKUP(G26,Setup!C:D,2,FALSE),"") -> 100000
B27: 25 | C27: =IF(D27="","",LEFT(SUBSTITUTE(UPPER(E27)," ",""),3)&"-"&TEXT(B27,"000")) -> IDI-025 | D27: FATUR | E27: IDINAN | F27: 10 | G27: =IFERROR(VLOOKUP(F27,Setup!B:C,2,FALSE),"") -> 10mbps | H27: =IFERROR(VLOOKUP(G27,Setup!C:D,2,FALSE),"") -> 100000
B28: 26 | C28: =IF(D28="","",LEFT(SUBSTITUTE(UPPER(E28)," ",""),3)&"-"&TEXT(B28,"000")) -> IDI-026 | D28: FIRMAN@SUPENOK | E28: IDINAN | F28: 10 | G28: =IFERROR(VLOOKUP(F28,Setup!B:C,2,FALSE),"") -> 10mbps | H28: =IFERROR(VLOOKUP(G28,Setup!C:D,2,FALSE),"") -> 100000
B29: 27 | C29: =IF(D29="","",LEFT(SUBSTITUTE(UPPER(E29)," ",""),3)&"-"&TEXT(B29,"000")) -> IDI-027 | D29: HENDI@ULWIYA | E29: IDINAN | F29: 10 | G29: =IFERROR(VLOOKUP(F29,Setup!B:C,2,FALSE),"") -> 10mbps | H29: =IFERROR(VLOOKUP(G29,Setup!C:D,2,FALSE),"") -> 100000
B30: 28 | C30: =IF(D30="","",LEFT(SUBSTITUTE(UPPER(E30)," ",""),3)&"-"&TEXT(B30,"000")) -> IDI-028 | D30: HOLIK | E30: IDINAN | F30: 10 | G30: =IFERROR(VLOOKUP(F30,Setup!B:C,2,FALSE),"") -> 10mbps | H30: =IFERROR(VLOOKUP(G30,Setup!C:D,2,FALSE),"") -> 100000
... B57: 55 | C57: =IF(D57="","",LEFT(SUBSTITUTE(UPPER(E57)," ",""),3)&"-"&TEXT(B57,"000")) -> IDI-055 | D57: ILHAM | E57: IDINAN | F57: 10 | G57: =IFERROR(VLOOKUP(F57,Setup!B:C,2,FALSE),"") -> 10mbps | H57: =IFERROR(VLOOKUP(G57,Setup!C:D,2,FALSE),"") -> 100000
B58: 56 | C58: =IF(D58="","",LEFT(SUBSTITUTE(UPPER(E58)," ",""),3)&"-"&TEXT(B58,"000")) -> IDI-056 | D58: ZEA | E58: IDINAN | F58: 20 | G58: =IFERROR(VLOOKUP(F58,Setup!B:C,2,FALSE),"") -> 20mbps | H58: 150000
B59: 57 | C59: =IF(D59="","",LEFT(SUBSTITUTE(UPPER(E59)," ",""),3)&"-"&TEXT(B59,"000")) -> IDI-057 | D59: SRI meca | E59: IDINAN | F59: 10 | G59: =IFERROR(VLOOKUP(F59,Setup!B:C,2,FALSE),"") -> 10mbps | H59: 50000
B60: 58 | C60: =IF(D60="","",LEFT(SUBSTITUTE(UPPER(E60)," ",""),3)&"-"&TEXT(B60,"000")) -> IDI-058 | D60: FAISOL | E60: IDINAN | F60: 10 | G60: =IFERROR(VLOOKUP(F60,Setup!B:C,2,FALSE),"") -> 10mbps | H60: 50000
B61: 59 | C61: =IF(D61="","",LEFT(SUBSTITUTE(UPPER(E61)," ",""),3)&"-"&TEXT(B61,"000")) -> IDI-059 | D61: JUNAIDI | E61: IDINAN | F61: 10 | G61: =IFERROR(VLOOKUP(F61,Setup!B:C,2,FALSE),"") -> 10mbps | H61: 50000
B62: 60 | C62: =IF(D62="","",LEFT(SUBSTITUTE(UPPER(E62)," ",""),3)&"-"&TEXT(B62,"000")) -> IDI-060 | D62: KOM | E62: IDINAN | F62: 10 | G62: =IFERROR(VLOOKUP(F62,Setup!B:C,2,FALSE),"") -> 10mbps | H62: 75000
B63: 61 | C63: =IF(D63="","",LEFT(SUBSTITUTE(UPPER(E63)," ",""),3)&"-"&TEXT(B63,"000")) -> IDI-061 | D63: ARIP@AYUK | E63: IDINAN | F63: 10 | G63: =IFERROR(VLOOKUP(F63,Setup!B:C,2,FALSE),"") -> 10mbps | H63: =IFERROR(VLOOKUP(G63,Setup!C:D,2,FALSE),"") -> 100000
B64: 62 | C64: =IF(D64="","",LEFT(SUBSTITUTE(UPPER(E64)," ",""),3)&"-"&TEXT(B64,"000")) -> IDI-062 | D64: DAYAT@BENGKEL | E64: IDINAN | F64: 10 | G64: =IFERROR(VLOOKUP(F64,Setup!B:C,2,FALSE),"") -> 10mbps | H64: =IFERROR(VLOOKUP(G64,Setup!C:D,2,FALSE),"") -> 100000
B65: 63 | C65: =IF(D65="","",LEFT(SUBSTITUTE(UPPER(E65)," ",""),3)&"-"&TEXT(B65,"000")) -> IDI-063 | D65: ANGGA@ANIS | E65: IDINAN | F65: 10 | G65: =IFERROR(VLOOKUP(F65,Setup!B:C,2,FALSE),"") -> 10mbps | H65: =IFERROR(VLOOKUP(G65,Setup!C:D,2,FALSE),"") -> 100000
B66: 64 | C66: =IF(D66="","",LEFT(SUBSTITUTE(UPPER(E66)," ",""),3)&"-"&TEXT(B66,"000")) -> TAN-064 | D66: ANJAS | E66: TANAH LOS | F66: 10 | G66: =IFERROR(VLOOKUP(F66,Setup!B:C,2,FALSE),"") -> 10mbps | H66: =IFERROR(VLOOKUP(G66,Setup!C:D,2,FALSE),"") -> 100000
...

Sheet Tagihan Pelanggan
B2: NO | C2: ID PELANGGAN | D2: NAMA PELANGGAN | E2: ALAMAT | F2: HARGA | G2: PEMBAYARAN | L2: KETERANGAN | M2: TAGIHAN BELUM LUNAS
G3: CASH | H3: BCA | I3: BRI | J3: MANDIRI | K3: BNI | M3: (RP) | N3: BULAN
B4: 1 | C4: =NamaPelanggan!C3 -> BLI-001 | D4: =NamaPelanggan!D3 -> BAIHAKI | E4: =NamaPelanggan!E3 -> BLIMBINGSARI | F4: =NamaPelanggan!H3 -> 100000 | I4: 100000 | L4: =IF(SUM(G4:K4)>0,"LUNAS","BELUM LUNAS") -> LUNAS
B5: 2 | C5: =NamaPelanggan!C4 -> BLI-002 | D5: =NamaPelanggan!D4 -> BEDENG@BANANA | E5: =NamaPelanggan!E4 -> BLIMBINGSARI | F5: =NamaPelanggan!H4 -> 100000 | I5: 100000 | L5: =IF(SUM(G5:K5)>0,"LUNAS","BELUM LUNAS") -> LUNAS | R5: =COUNTIF(L4:L601,"LUNAS") -> 413
B6: 3 | C6: =NamaPelanggan!C5 -> BLI-003 | D6: =NamaPelanggan!D5 -> DITA@NOK | E6: =NamaPelanggan!E5 -> BLIMBINGSARI | F6: =NamaPelanggan!H5 -> 100000 | I6: 100000 | L6: =IF(SUM(G6:K6)>0,"LUNAS","BELUM LUNAS") -> LUNAS | R6: =COUNTIF(L4:L601,"BELUM LUNAS") -> 85 | S6: 75
B7: 4 | C7: =NamaPelanggan!C6 -> BLI-004 | D7: =NamaPelanggan!D6 -> FIKRISEI | E7: =NamaPelanggan!E6 -> BLIMBINGSARI | F7: =NamaPelanggan!H6 -> 100000 | I7: 100000 | L7: =IF(SUM(G7:K7)>0,"LUNAS","BELUM LUNAS") -> LUNAS
B8: 5 | C8: =NamaPelanggan!C7 -> BLI-005 | D8: =NamaPelanggan!D7 -> MISTARA@YONO | E8: =NamaPelanggan!E7 -> BLIMBINGSARI | F8: =NamaPelanggan!H7 -> 100000 | I8: 100000 | L8: =IF(SUM(G8:K8)>0,"LUNAS","BELUM LUNAS") -> LUNAS
B9: 6 | C9: =NamaPelanggan!C8 -> BLI-006 | D9: =NamaPelanggan!D8 -> NAFIZ@MI | E9: =NamaPelanggan!E8 -> BLIMBINGSARI | F9: =NamaPelanggan!H8 -> 100000 | I9: 100000 | L9: =IF(SUM(G9:K9)>0,"LUNAS","BELUM LUNAS") -> LUNAS | Q9: NO | R9: ID PELANGGAN | S9: NAMA PELANGGAN | T9: ALAMAT | U9: TOTAL TAGIHAN
B10: 7 | C10: =NamaPelanggan!C9 -> BLI-007 | D10: =NamaPelanggan!D9 -> PETRUK | E10: =NamaPelanggan!E9 -> BLIMBINGSARI | F10: =NamaPelanggan!H9 -> 100000 | I10: 200000 | L10: =IF(SUM(G10:K10)>0,"LUNAS","BELUM LUNAS") -> LUNAS | Q10: 1 | R10: {=_xlfn._xlws.FILTER(C:C,L:L="BELUM LUNAS","")} -> BLI-013 | S10: {=_xlfn._xlws.FILTER(D:D,L:L="BELUM LUNAS","Tidak AdA")} -> elisha | T10: {=_xlfn._xlws.FILTER(E:E,L:L="BELUM LUNAS","")} -> BLIMBINGSARI | U10: {=_xlfn._xlws.FILTER(M$1:M$65536,L$1:L$65536="BELUM LUNAS","")} -> 100000
B11: 8 | C11: =NamaPelanggan!C10 -> BLI-008 | D11: =NamaPelanggan!D10 -> SABU | E11: =NamaPelanggan!E10 -> BLIMBINGSARI | F11: =NamaPelanggan!H10 -> 100000 | I11: 100000 | L11: =IF(SUM(G11:K11)>0,"LUNAS","BELUM LUNAS") -> LUNAS | Q11: 2 | R11: BLI-018 | S11: MES@BMT | T11: BLIMBINGSARI | U11: 100000
B12: 9 | C12: =NamaPelanggan!C11 -> BLI-009 | D12: =NamaPelanggan!D11 -> SAROH@ANDIK | E12: =NamaPelanggan!E11 -> BLIMBINGSARI | F12: =NamaPelanggan!H11 -> 100000 | I12: 100000 | L12: =IF(SUM(G12:K12)>0,"LUNAS","BELUM LUNAS") -> LUNAS | Q12: 3 | R12: IDI-024 | S12: ELOK | T12: IDINAN | U12: 100000
B13: 10 | C13: =NamaPelanggan!C12 -> BLI-010 | D13: =NamaPelanggan!D12 -> SUNARYU | E13: =NamaPelanggan!E12 -> BLIMBINGSARI | F13: =NamaPelanggan!H12 -> 100000 | I13: 100000 | L13: =IF(SUM(G13:K13)>0,"LUNAS","BELUM LUNAS") -> LUNAS | Q13: 4 | R13: IDI-027 | S13: HENDI@ULWIYA | T13: IDINAN | U13: 100000
B14: 11 | C14: =NamaPelanggan!C13 -> BLI-011 | D14: =NamaPelanggan!D13 -> lia muji | E14: =NamaPelanggan!E13 -> BLIMBINGSARI | F14: =NamaPelanggan!H13 -> 100000 | I14: 200000 | L14: =IF(SUM(G14:K14)>0,"LUNAS","BELUM LUNAS") -> LUNAS | Q14: 5 | R14: IDI-028 | S14: HOLIK | T14: IDINAN | U14: 100000
B15: 12 | C15: =NamaPelanggan!C14 -> BLI-012 | D15: =NamaPelanggan!D14 -> YUSUF | E15: =NamaPelanggan!E14 -> BLIMBINGSARI | F15: =NamaPelanggan!H14 -> 100000 | I15: 100000 | L15: =IF(SUM(G15:K15)>0,"LUNAS","BELUM LUNAS") -> LUNAS | Q15: 6 | R15: IDI-043 | S15: SOLFI@FERI | T15: IDINAN | U15: 100000
B16: 13 | C16: =NamaPelanggan!C15 -> BLI-013 | D16: =NamaPelanggan!D15 -> elisha | E16: =NamaPelanggan!E15 -> BLIMBINGSARI | F16: =NamaPelanggan!H15 -> 100000 | L16: =IF(SUM(G16:K16)>0,"LUNAS","BELUM LUNAS") -> BELUM LUNAS | M16: 100000 | N16: mei | Q16: 7 | R16: IDI-061 | S16: ARIP@AYUK | T16: IDINAN | U16: 800000
B17: 14 | C17: =NamaPelanggan!C16 -> BLI-014 | D17: =NamaPelanggan!D16 -> SANTI | E17: =NamaPelanggan!E16 -> BLIMBINGSARI | F17: =NamaPelanggan!H16 -> 50000 | I17: 50000 | L17: =IF(SUM(G17:K17)>0,"LUNAS","BELUM LUNAS") -> LUNAS | Q17: 8 | R17: IDI-062 | S17: DAYAT@BENGKEL | T17: IDINAN | U17: 400000
B18: 15 | C18: =NamaPelanggan!C17 -> BLI-015 | D18: =NamaPelanggan!D17 -> ROMI | E18: =NamaPelanggan!E17 -> BLIMBINGSARI | F18: =NamaPelanggan!H17 -> 50000 | I18: 50000 | L18: =IF(SUM(G18:K18)>0,"LUNAS","BELUM LUNAS") -> LUNAS | Q18: 9 | R18: TAN-065 | S18: ALIP@BINTANG | T18: TANAH LOS | U18: 100000
B19: 16 | C19: =NamaPelanggan!C18 -> BLI-016 | D19: =NamaPelanggan!D18 -> MI@SUNANGIRI | E19: =NamaPelanggan!E18 -> BLIMBINGSARI | F19: =NamaPelanggan!H18 -> 50000 | I19: 100000 | L19: =IF(SUM(G19:K19)>0,"LUNAS","BELUM LUNAS") -> LUNAS | Q19: 10 | R19: TAN-066 | S19: ANA@HAR | T19: TANAH LOS | U19: 100000
B20: 17 | C20: =NamaPelanggan!C19 -> BLI-017 | D20: =NamaPelanggan!D19 -> MES@BANANA | E20: =NamaPelanggan!E19 -> BLIMBINGSARI | F20: =NamaPelanggan!H19 -> 100000 | I20: 100000 | L20: =IF(SUM(G20:K20)>0,"LUNAS","BELUM LUNAS") -> LUNAS | Q20: 11 | R20: TAN-069 | S20: DIKI@HELMI | T20: TANAH LOS | U20: 100000
B21: 18 | C21: =NamaPelanggan!C20 -> BLI-018 | D21: =NamaPelanggan!D20 -> MES@BMT | E21: =NamaPelanggan!E20 -> BLIMBINGSARI | F21: =NamaPelanggan!H20 -> 100000 | L21: =IF(SUM(G21:K21)>0,"LUNAS","BELUM LUNAS") -> BELUM LUNAS | M21: 100000 | N21: MEI | Q21: 12 | R21: TAN-070 | S21: selamet dinda / ima | T21: TANAH LOS | U21: 100000
B22: 19 | C22: =NamaPelanggan!C21 -> IDI-019 | D22: =NamaPelanggan!D21 -> AKBARR | E22: =NamaPelanggan!E21 -> IDINAN | F22: =NamaPelanggan!H21 -> 100000 | I22: 100000 | L22: =IF(SUM(G22:K22)>0,"LUNAS","BELUM LUNAS") -> LUNAS | Q22: 13 | R22: TAN-094 | S22: marcel | T22: TANAH LOS | U22: 100000
B23: 20 | C23: =NamaPelanggan!C22 -> IDI-020 | D23: =NamaPelanggan!D22 -> AKSORO | E23: =NamaPelanggan!E22 -> IDINAN | F23: =NamaPelanggan!H22 -> 100000 | I23: 100000 | L23: =IF(SUM(G23:K23)>0,"LUNAS","BELUM LUNAS") -> LUNAS | Q23: 14 | R23: TAN-102 | S23: SITISP | T23: TANAH LOS | U23: 400000
B24: 21 | C24: =NamaPelanggan!C23 -> IDI-021 | D24: =NamaPelanggan!D23 -> ALFI@SUN ( TERUSAN ) blimbing | E24: =NamaPelanggan!E23 -> IDINAN | F24: =NamaPelanggan!H23 -> 100000 | I24: 100000 | L24: =IF(SUM(G24:K24)>0,"LUNAS","BELUM LUNAS") -> LUNAS | Q24: 15 | R24: JAM-116 | S24: ERPAN | T24: JAMBU | U24: 100000
B25: 22 | C25: =NamaPelanggan!C24 -> IDI-022 | D25: =NamaPelanggan!D24 -> ASIS | E25: =NamaPelanggan!E24 -> IDINAN | F25: =NamaPelanggan!H24 -> 100000 | I25: 100000 | L25: =IF(SUM(G25:K25)>0,"LUNAS","BELUM LUNAS") -> LUNAS | Q25: 16 | R25: JAM-122 | S25: JONO@EVA | T25: JAMBU | U25: 100000
B26: 23 | C26: =NamaPelanggan!C25 -> IDI-023 | D26: =NamaPelanggan!D25 -> AYULESTARI | E26: =NamaPelanggan!E25 -> IDINAN | F26: =NamaPelanggan!H25 -> 100000 | I26: 100000 | L26: =IF(SUM(G26:K26)>0,"LUNAS","BELUM LUNAS") -> LUNAS | Q26: 17 | R26: JAM-132 | S26: PUTRIUNTUNG | T26: JAMBU | U26: 100000
B27: 24 | C27: =NamaPelanggan!C26 -> IDI-024 | D27: =NamaPelanggan!D26 -> ELOK | E27: =NamaPelanggan!E26 -> IDINAN | F27: =NamaPelanggan!H26 -> 100000 | I27: 200000 | L27: BELUM LUNAS | M27: 100000 | N27: april | Q27: 18 | R27: JAM-134 | S27: RIRIN | T27: JAMBU | U27: 100000
B28: 25 | C28: =NamaPelanggan!C27 -> IDI-025 | D28: =NamaPelanggan!D27 -> FATUR | E28: =NamaPelanggan!E27 -> IDINAN | F28: =NamaPelanggan!H27 -> 100000 | I28: 100000 | L28: =IF(SUM(G28:K28)>0,"LUNAS","BELUM LUNAS") -> LUNAS | Q28: 19 | R28: JAM-135 | S28: SERATEM / chandra | T28: JAMBU | U28: 100000
B29: 26 | C29: =NamaPelanggan!C28 -> IDI-026 | D29: =NamaPelanggan!D28 -> FIRMAN@SUPENOK | E29: =NamaPelanggan!E28 -> IDINAN | F29: =NamaPelanggan!H28 -> 100000 | I29: 100000 | L29: =IF(SUM(G29:K29)>0,"LUNAS","BELUM LUNAS") -> LUNAS | Q29: 20 | R29: JAM-145 | S29: YURIS@ALVIN | T29: JAMBU | U29: 100000
B30: 27 | C30: =NamaPelanggan!C29 -> IDI-027 | D30: =NamaPelanggan!D29 -> HENDI@ULWIYA | E30: =NamaPelanggan!E29 -> IDINAN | F30: =NamaPelanggan!H29 -> 100000 | L30: =IF(SUM(G30:K30)>0,"LUNAS","BELUM LUNAS") -> BELUM LUNAS | M30: 100000 | N30: mei | Q30: 21 | R30: JAM-181 | S30: KORAMIL | T30: JAMBU | U30: 50000
B31: 28 | C31: =NamaPelanggan!C30 -> IDI-028 | D31: =NamaPelanggan!D30 -> HOLIK | E31: =NamaPelanggan!E30 -> IDINAN | F31: =NamaPelanggan!H30 -> 100000 | L31: =IF(SUM(G31:K31)>0,"LUNAS","BELUM LUNAS") -> BELUM LUNAS | M31: 100000 | N31: mei | Q31: 22 | R31: JAM-189 | S31: LURAH | T31: JAMBU | U31: 500000
B32: 29 | C32: =NamaPelanggan!C31 -> IDI-029 | D32: =NamaPelanggan!D31 -> OMAN | E32: =NamaPelanggan!E31 -> IDINAN | F32: =NamaPelanggan!H31 -> 100000 | I32: 100000 | L32: =IF(SUM(G32:K32)>0,"LUNAS","BELUM LUNAS") -> LUNAS | Q32: 23 | R32: JAM-192 | S32: DEOMAH@OSENG | T32: JAMBU | U32: 600000
B33: 30 | C33: =NamaPelanggan!C32 -> IDI-030 | D33: =NamaPelanggan!D32 -> ILHAM@OMAN | E33: =NamaPelanggan!E32 -> IDINAN | F33: =NamaPelanggan!H32 -> 100000 | I33: 100000 | L33: =IF(SUM(G33:K33)>0,"LUNAS","BELUM LUNAS") -> LUNAS | Q33: 24 | R33: JAM-193 | S33: AROMATIKA | T33: JAMBU | U33: 200000
B34: 31 | C34: =NamaPelanggan!C33 -> IDI-031 | D34: =NamaPelanggan!D33 -> JUNET@JUN | E34: =NamaPelanggan!E33 -> IDINAN | F34: =NamaPelanggan!H33 -> 100000 | I34: 100000 | L34: =IF(SUM(G34:K34)>0,"LUNAS","BELUM LUNAS") -> LUNAS | Q34: 25 | R34: JAM-194 | S34: P.YANI | T34: JAMBU | U34: 100000
B35: 32 | C35: =NamaPelanggan!C34 -> IDI-032 | D35: =NamaPelanggan!D34 -> MATTAIN | E35: =NamaPelanggan!E34 -> IDINAN | F35: =NamaPelanggan!H34 -> 100000 | I35: 100000 | L35: =IF(SUM(G35:K35)>0,"LUNAS","BELUM LUNAS") -> LUNAS | Q35: 26 | R35: JAM-195 | S35: PELANGI | T35: JAMBU | U35: 100000
B36: 33 | C36: =NamaPelanggan!C35 -> IDI-033 | D36: =NamaPelanggan!D35 -> LIAUDIK | E36: =NamaPelanggan!E35 -> IDINAN | F36: =NamaPelanggan!H35 -> 100000 | I36: 100000 | L36: =IF(SUM(G36:K36)>0,"LUNAS","BELUM LUNAS") -> LUNAS | Q36: 27 | R36: JAM-196 | S36: SDN4 | T36: JAMBU | U36: 750000
B37: 34 | C37: =NamaPelanggan!C36 -> IDI-034 | D37: =NamaPelanggan!D36 -> LUTFI | E37: =NamaPelanggan!E36 -> IDINAN | F37: =NamaPelanggan!H36 -> 100000 | I37: 100000 | L37: =IF(SUM(G37:K37)>0,"LUNAS","BELUM LUNAS") -> LUNAS | Q37: 28 | R37: JAM-197 | S37: SUNOTOK | T37: JAMBU | U37: 375000
B38: 35 | C38: =NamaPelanggan!C37 -> IDI-035 | D38: =NamaPelanggan!D37 -> MARIMIN | E38: =NamaPelanggan!E37 -> IDINAN | F38: =NamaPelanggan!H37 -> 100000 | I38: 100000 | L38: =IF(SUM(G38:K38)>0,"LUNAS","BELUM LUNAS") -> LUNAS | Q38: 29 | R38: JAM-200 | S38: SUYONO/ susiyono | T38: JAMBU | U38: 75000
B39: 36 | C39: =NamaPelanggan!C38 -> IDI-036 | D39: =NamaPelanggan!D38 -> OPIK | E39: =NamaPelanggan!E38 -> IDINAN | F39: =NamaPelanggan!H38 -> 100000 | I39: 200000 | L39: =IF(SUM(G39:K39)>0,"LUNAS","BELUM LUNAS") -> LUNAS | M39: 100000 | N39: april | Q39: 30 | R39: JAM-201 | S39: OOT@JIDAN | T39: JAMBU | U39: 100000
B40: 37 | C40: =NamaPelanggan!C39 -> IDI-037 | D40: =NamaPelanggan!D39 -> P.ARI | E40: =NamaPelanggan!E39 -> IDINAN | F40: =NamaPelanggan!H39 -> 100000 | I40: 100000 | L40: =IF(SUM(G40:K40)>0,"LUNAS","BELUM LUNAS") -> LUNAS | Q40: 31 | R40: AMP-208 | S40: ADIT | T40: AMPELGADING | U40: 100000
B41: 38 | C41: =NamaPelanggan!C40 -> IDI-038 | D41: =NamaPelanggan!D40 -> P.LULUK@IDINAN | E41: =NamaPelanggan!E40 -> IDINAN | F41: =NamaPelanggan!H40 -> 100000 | I41: 100000 | L41: =IF(SUM(G41:K41)>0,"LUNAS","BELUM LUNAS") -> LUNAS | Q41: 32 | R41: AMP-210 | S41: B.IPUL | T41: AMPELGADING | U41: 100000
...

Sheet Pengeluaran
B2: NO | C2: TANGGAL | D2: URAIAN | E2: JUMLAH | F2: TOTAL :
B3: 1 | C3: 11 mei 2026 | D3: mas fany fee | E3: 290000 | F3: =SUM(E3:E93) -> 1915000
B4: 2 | C4: 13 mei 2026 | D4: fee p.ulan | E4: 65000
B5: 3 | C5: 13 mei 2026 | D5: mba ida fee | E5: 560000
B6: 4 | C6: 13 mei 2026 | D6: mas fany fee | E6: 225000
B7: 5 | C7: 14 mei 2026 | D7: mba lili fee | E7: 235000
B8: 6 | C8: 16 mei 2026 | D8: mba dita fee | E8: 325000
B9: 7 | C9: 19 mei 2026 | D9: mas fany fee | E9: 70000
B10: 8 | C10: 21 mei 2026 | D10: fee mba yuni | E10: 55000
B11: 9 | C11: 2 juni 2026 | D11: mas fany fee | E11: 90000
B12: 17
B13: 18
B14: 19
B15: 20
B16: 21
B17: 22
B18: 23
B19: 24
B20: 25
B21: 26
B22: 27
B23: 28
... B25: 30

Sheet Setup
B2: KODE PAKET | C2: PAKET | D2: HARGA
B3: 10 | C3: 10mbps | D3: 100000
B4: 20 | C4: 20mbps | D4: 200000
B5: 30 | C5: 30mbps | D5: 250000
B6: 50 | C6: 50mbps | D6: 350000
B7: 100 | C7: 100mbps | D7: 1850000
B8: 200 | C8: 200Mbps | D8: 3700000
B9: 300 | C9: 300Mbps | D9: 5550000
B10: 400 | C10: 400Mbps | D10: 7400000
B11: 500 | C11: 500Mbps | D11: 9250000
B12: 600 | C12: 600Mbps | D12: 11100000

Sheet Read Me
B3: DASHBOARD PEMBAYARAN TAGIHAN WIFI
B6: Tentang:
B7: Template ini mempermudah pengelolaan usaha Wifi dengan fitur dashboard ringkasan, pencatatan biaya operasional, Semua terintegrasi untuk mempermudah manajemen usaha wifi.
B11: Panduan:
B12: 1. Sebelum mulai menggunakan template, sesuaikan dulu jenis layanan paket wifi,kode paket dan harga ada di menu setup ⚙️
B13: 2. Sheet Dashboard🖥️ dapat Anda gunakan untuk melihat ringkasan laporan keuangan usaha wifi Anda. Semua data yang Anda butuhkan dapat Anda lihat hanya dalam satu sheet
B14: 3. Pada sheet Nama Pelanggan, masukkan semua data tiap pelanggan wifi.
B15: 4. Pada sheet Tagihan Pelanggan Sebagian sudah terintrigasi dengan shet nama pelanggan, tinggal isi dikolom pembayaran dan tagihan belum lunas.
B17: Saran Penggunaan :
B18: ⚠️ disarankan untuk menggunakan laptop atau tablet, disarankan untuk tidak menghapus kolom yang sudah ada rumusnya
B20: Catatan:
B21: ⚠️ Sejumlah fitur pada spreadsheet ini kemungkinan belum support jika digunakan melalui aplikasi Microsoft Excel. Untuk penggunaan maksimal, pastikan hanya melakukan editing melalui Google Sheet.
B24: Terima kasih karena sudah menggunakan spreadsheet ini! :D
